Workbook
Name btbl2: diets!$A$76
Name btbl4fn1: diets!$A$5
Name btbl4fn10: diets!$A$39
Name btbl4fn11: diets!$A$40
Name btbl4fn12: diets!$A$43
Name btbl4fn13: diets!$A$44
Name btbl4fn2: diets!$A$14
Name btbl4fn3: diets!$A$16
Name btbl4fn4: diets!$A$18
Name btbl4fn5: diets!$A$19
Name btbl4fn6: diets!$A$24
Name btbl4fn7: diets!$A$26
Name btbl4fn8: diets!$A$33
Name btbl4fn9: diets!$A$38

Sheet Table of Contents
A3: Diets | B3: diets
A4: Nutrient compostion tables | B4: nutrient content
A5: Enviromental Data | B5: enviro
A6: Summary of Results | B6: summary

Sheet diets
B1: Reference approach | C1: Alternative approaches | I1: coefficents used | V1: Mean American Diet | AE1: UPF | AP1: 0.8 g/kg | AY1: 1.2 g/kg | BJ1: 1.6 g/kg | BU1: 1.6 g/kg plants | CF1: 1.6 g/kg animal
A2: food groups | B2: Absolute (kcal/d) | C2: Relative (% of total energy intake) | D2: Absolute (kcal/d) | E2: Relative (% of total energy intake) | F2: mass content (g/d) | G2: protein content (g/d) | I2: caloric density (kcal/g) | J2: protein content (g protein/g) | K2: LAND Needs, loss-adjusted (m2-yr/1g) | L2: NR needs, loss-adjusted (gNr/1g) | M2: WATER SCARCITY FOOTPRINT (liter eq./g) | N2: GHGE (kgCO2eq/1g) | O2: notes on enviromental data | U2: Absolute (kcal/d) | V2: Relative (% of total energy intake) | W2: mass content (g/d) | X2: protein content (g protein/d) | Y2: LAND Needs, loss-adjusted (m2-yr/d) | Z2: NR needs, loss-adjusted (gNr/d) | AA2: WATER SCARCITY FOOTPRINT (liter eq/d) | AB2: GHGE (kgCO2eq/d) | AE2: Absolute (kcal/d) | AF2: Relative (% of total energy intake) | AG2: mass content (g/d) | AH2: protein content (g protein/d) | AI2: LAND Needs, loss-adjusted (m2-yr/d) | AJ2: NR needs, loss-adjusted (gNr/d) | AK2: WATER SCARCITY FOOTPRINT (liter eq./d) | AL2: GHGE (kgCO2eq/d) | AO2: Absolute (kcal/d) | AP2: Relative (% of total energy intake) | AQ2: mass content (g/d) | AR2: protein content (g protein/d) | AS2: LAND Needs, loss-adjusted (m2-yr/d) | AT2: NR needs, loss-adjusted (gNr/d) | AU2: WATER SCARCITY FOOTPRINT (liter eq./d) | AV2: GHGE (kgCO2eq/d) | AY2: Absolute (kcal/d) | AZ2: Relative (% of total energy intake) | BA2: mass content (g/d) | BB2: protein content (g protein/d) | BC2: LAND Needs, loss-adjusted (m2-yr/d) | BD2: NR needs, loss-adjusted (gNr/d) | BE2: WATER SCARCITY FOOTPRINT (liter eq./d) | BF2: GHGE (kgCO2eq/d) | BJ2: Absolute (kcal/d) | BK2: Relative (% of total energy intake) | BL2: mass content (g/d) | BM2: protein content (g protein/d) | BN2: LAND Needs, loss-adjusted (m2-yr/d) | BO2: NR needs, loss-adjusted (gNr/d) | BP2: WATER SCARCITY FOOTPRINT (liter eq/d) | BQ2: GHGE (kgCO2eq/d) | BU2: Absolute (kcal/d) | BV2: Relative (% of total energy intake) | BW2: mass content (g/d) | BX2: protein content (g protein/d) | BY2: LAND Needs, loss-adjusted (m2-yr/d) | BZ2: NR needs, loss-adjusted (gNr/d) | CA2: WATER SCARCITY FOOTPRINT (liter eq/d) | CB2: GHGE (kgCO2eq/d) | CF2: Absolute (kcal/d) | CG2: Relative (% of total energy intake) | CH2: mass content (g/d) | CI2: protein content (g protein/d) | CJ2: LAND Needs, loss-adjusted (m2-yr/d) | CK2: NR needs, loss-adjusted (gNr/d) | CL2: WATER SCARCITY FOOTPRINT (liter eq/d) | CM2: GHGE (kgCO2eq/d)
A3: Unprocessed or minimally processed foods | B3: 547 | C3: 27.6 | D3: 510.6 (11.5) | E3: 26.0 (0.6)
A4: Meat (includes poultry) | B4: 136.2 | C4: 6.5 | D4: 125.3 (5.4) | E4: 6.0 (0.2) | F4: =B4/I4 -> 72.466081 | G4: =F4*J4 -> 14.393575 | I4: =0.5*'nutrient content'!L189/100+0.5*'nutrient content'!L190/100 -> 1.8795 | J4: =0.5*'nutrient content'!M189/100+0.5*'nutrient content'!M190/100 -> 0.198625 | K4: =AVERAGE(enviro!AD18,enviro!AD19) -> 0.1771852 | L4: =AVERAGE(enviro!AE18,enviro!AE19) -> 0.29670449 | M4: =AVERAGE(enviro!AF18,enviro!AF19) -> 6.8195412 | N4: =AVERAGE(enviro!AG18,enviro!AG19) -> 0.013680883 | O4: assume 50% poultry and 50% meat | U4: =B4 -> 136.2 | W4: =U4/I4 -> 72.466081 | X4: =W4*J4 -> 14.393575 | Y4: =$W4*K4 -> 12.839917 | Z4: =$W4*L4 -> 21.501012 | AA4: =$W4*M4 -> 494.18543 | AB4: =$W4*N4 -> 0.99139996 | AE4: 0 | AG4: =AE4/I4 -> 0 | AH4: =AG4*J4 -> 0 | AI4: =$AG4*K4 -> 0 | AJ4: =$AG4*L4 -> 0 | AK4: =$AG4*M4 -> 0 | AL4: =$AG4*N4 -> 0 | AO4: =AQ4*I4 -> 147.00771 | AQ4: 78.216393 | AR4: =AQ4*J4 -> 15.535731 | AS4: =AQ4*K4 -> 13.858787 | AT4: =AQ4*L4 -> 23.207155 | AU4: =AQ4*M4 -> 533.39991 | AV4: =AQ4*N4 -> 1.0700693 | AY4: =BA4*I4 -> 175.29214 | BA4: 93.265302 | BB4: =BA4*J4 -> 18.524821 | BC4: =BA4*K4 -> 16.525231 | BD4: =BA4*L4 -> 27.672234 | BE4: =BA4*M4 -> 636.02657 | BF4: =BA4*N4 -> 1.2759517 | BJ4: =BL4*I4 -> 212.1985 | BL4: 112.90157 | BM4: =BL4*J4 -> 22.425074 | BN4: =BL4*K4 -> 20.004486 | BO4: =BL4*L4 -> 33.498402 | BP4: =BL4*M4 -> 769.9369 | BQ4: =BL4*N4 -> 1.5445931 | BU4: =BW4*I4 -> 69.5415 | BW4: 37 | BX4: =BW4*J4 -> 7.349125 | BY4: =BW4*K4 -> 6.5558522 | BZ4: =BW4*L4 -> 10.978066 | CA4: =BW4*M4 -> 252.32302 | CB4: =BW4*N4 -> 0.50619266 | CF4: =CH4*I4 -> 231.26566 | CH4: 123.04638 | CI4: =CH4*J4 -> 24.440086 | CJ4: =CH4*K4 -> 21.801996 | CK4: =CH4*L4 -> 36.508412 | CL4: =CH4*M4 -> 839.11983 | CM4: =CH4*N4 -> 1.683383
A5: Fruit | B5: 82.9 | C5: 4.4 | D5: 82.9 (3.2) | E5: 4.4 (0.2) | F5: =B5/I5 -> 95.749916 | G5: =F5*J5 -> 0.95888684 | I5: ='nutrient content'!$B$153/100 -> 0.8657971 | J5: ='nutrient content'!C153/100 -> 0.010014493 | K5: =enviro!AD11 -> 0.0023035092 | L5: =enviro!AE11 -> 0.026136647 | M5: =enviro!AF11 -> 2.6729545 | N5: =enviro!AG11 -> 0.0006384849 | U5: =B5 -> 82.9 | W5: =U5/I5 -> 95.749916 | X5: =W5*J5 -> 0.95888684 | Y5: =$W5*K5 -> 0.22056081 | Z5: =$W5*L5 -> 2.5025818 | AA5: =$W5*M5 -> 255.93517 | AB5: =$W5*N5 -> 0.061134876 | AE5: 0 | AG5: =AE5/I5 -> 0 | AH5: =AG5*J5 -> 0 | AI5: =$AG5*K5 -> 0 | AJ5: =$AG5*L5 -> 0 | AK5: =$AG5*M5 -> 0 | AL5: =$AG5*N5 -> 0 | AO5: =AQ5*I5 -> 88.510088 | AQ5: 102.2296 | AR5: =AQ5*J5 -> 1.0237775 | AS5: =AQ5*K5 -> 0.23548681 | AT5: =AQ5*L5 -> 2.6719389 | AU5: =AQ5*M5 -> 273.25506 | AV5: =AQ5*N5 -> 0.065272053 | AY5: =BA5*I5 -> 88.65874 | BA5: 102.40129 | BB5: =BA5*J5 -> 1.025497 | BC5: =BA5*K5 -> 0.23588231 | BD5: =BA5*L5 -> 2.6764264 | BE5: =BA5*M5 -> 273.71399 | BF5: =BA5*N5 -> 0.065381677 | BJ5: =BL5*I5 -> 88.539352 | BL5: 102.2634 | BM5: =BL5*J5 -> 1.024116 | BN5: =BL5*K5 -> 0.23556467 | BO5: =BL5*L5 -> 2.6728223 | BP5: =BL5*M5 -> 273.34541 | BQ5: =BL5*N5 -> 0.065293634 | BU5: =BW5*I5 -> 91.558043 | BW5: 105.75 | BX5: =BW5*J5 -> 1.0590326 | BY5: =BW5*K5 -> 0.2435961 | BZ5: =BW5*L5 -> 2.7639505 | CA5: =BW5*M5 -> 282.66494 | CB5: =BW5*N5 -> 0.067519778 | CF5: =CH5*I5 -> 8.657971 | CH5: 10 | CI5: =CH5*J5 -> 0.10014493 | CJ5: =CH5*K5 -> 0.023035092 | CK5: =CH5*L5 -> 0.26136647 | CL5: =CH5*M5 -> 26.729545 | CM5: =CH5*N5 -> 0.006384849
A6: Milk and plain yogurt | B6: 70.7 | C6: 3.7 | D6: 70.7 (2.8) | E6: 3.7 (0.2) | F6: =B6/I6 -> 46.085123 | G6: =F6*J6 -> 4.3347124 | I6: ='nutrient content'!L210/100 -> 1.5341176 | J6: ='nutrient content'!M210/100 -> 0.094058824 | K6: =enviro!AD8 -> 0.020793191 | L6: =enviro!AE8 -> 0.061135714 | M6: =enviro!AF8 -> 8.6341785 | N6: =enviro!AG8 -> 0.0038352347 | U6: =B6 -> 70.7 | W6: =U6/I6 -> 46.085123 | X6: =W6*J6 -> 4.3347124 | Y6: =$W6*K6 -> 0.95825676 | Z6: =$W6*L6 -> 2.8174469 | AA6: =$W6*M6 -> 397.90718 | AB6: =$W6*N6 -> 0.17674726 | AE6: 0 | AG6: =AE6/I6 -> 0 | AH6: =AG6*J6 -> 0 | AI6: =$AG6*K6 -> 0 | AJ6: =$AG6*L6 -> 0 | AK6: =$AG6*M6 -> 0 | AL6: =$AG6*N6 -> 0 | AO6: =AQ6*I6 -> 80.238424 | AQ6: 52.302654 | AR6: =AQ6*J6 -> 4.9195261 | AS6: =AQ6*K6 -> 1.0875391 | AT6: =AQ6*L6 -> 3.1975601 | AU6: =AQ6*M6 -> 451.59045 | AV6: =AQ6*N6 -> 0.20059295 | AY6: =BA6*I6 -> 91.723163 | BA6: 59.788872 | BB6: =BA6*J6 -> 5.6236709 | BC6: =BA6*K6 -> 1.2432014 | BD6: =BA6*L6 -> 3.6552353 | BE6: =BA6*M6 -> 516.22779 | BF6: =BA6*N6 -> 0.22930435 | BJ6: =BL6*I6 -> 102.68415 | BL6: 66.933685 | BM6: =BL6*J6 -> 6.2957036 | BN6: =BL6*K6 -> 1.3917649 | BO6: =BL6*L6 -> 4.0920386 | BP6: =BL6*M6 -> 577.91738 | BQ6: =BL6*N6 -> 0.25670639 | BU6: =BW6*I6 -> 56.762353 | BW6: 37 | BX6: =BW6*J6 -> 3.4801765 | BY6: =BW6*K6 -> 0.76934807 | BZ6: =BW6*L6 -> 2.2620214 | CA6: =BW6*M6 -> 319.46461 | CB6: =BW6*N6 -> 0.14190368 | CF6: =CH6*I6 -> 111.02983 | CH6: 72.373741 | CI6: =CH6*J6 -> 6.8073889 | CJ6: =CH6*K6 -> 1.504881 | CK6: =CH6*L6 -> 4.4246203 | CL6: =CH6*M6 -> 624.8878 | CM6: =CH6*N6 -> 0.27757028
A7: Grains | B7: 59.3 | C7: 3 | D7: 48.4 (4.1) | E7: 2.6 (0.2) | F7: =B7/I7 -> 16.872737 | G7: =F7*J7 -> 2.4020641 | I7: ='nutrient content'!B44/100 -> 3.5145455 | J7: ='nutrient content'!C44/100 -> 0.14236364 | K7: =enviro!AD13 -> 0.0058084261 | L7: =enviro!AE13 -> 0.095654114 | M7: =enviro!AF13 -> 0.92625253 | N7: =enviro!AG13 -> 0.00044056356 | U7: =B7 -> 59.3 | W7: =U7/I7 -> 16.872737 | X7: =W7*J7 -> 2.4020641 | Y7: =$W7*K7 -> 0.098004045 | Z7: =$W7*L7 -> 1.6139467 | AA7: =$W7*M7 -> 15.628415 | AB7: =$W7*N7 -> 0.0074335129 | AE7: 0 | AG7: =AE7/I7 -> 0 | AH7: =AG7*J7 -> 0 | AI7: =$AG7*K7 -> 0 | AJ7: =$AG7*L7 -> 0 | AK7: =$AG7*M7 -> 0 | AL7: =$AG7*N7 -> 0 | AO7: =AQ7*I7 -> 80.704278 | AQ7: 22.962935 | AR7: =AQ7*J7 -> 3.2690869 | AS7: =AQ7*K7 -> 0.13337851 | AT7: =AQ7*L7 -> 2.1964992 | AU7: =AQ7*M7 -> 21.269476 | AV7: =AQ7*N7 -> 0.010116632 | AY7: =BA7*I7 -> 159.38768 | BA7: 45.350867 | BB7: =BA7*J7 -> 6.4563144 | BC7: =BA7*K7 -> 0.26341716 | BD7: =BA7*L7 -> 4.337997 | BE7: =BA7*M7 -> 42.006355 | BF7: =BA7*N7 -> 0.01997994 | BJ7: =BL7*I7 -> 188.62767 | BL7: 53.670573 | BM7: =BL7*J7 -> 7.6407379 | BN7: =BL7*K7 -> 0.31174156 | BO7: =BL7*L7 -> 5.1338111 | BP7: =BL7*M7 -> 49.712503 | BQ7: =BL7*N7 -> 0.023645299 | BU7: =BW7*I7 -> 358.30535 | BW7: 101.94927 | BX7: =BW7*J7 -> 14.513869 | BY7: =BW7*K7 -> 0.59216481 | BZ7: =BW7*L7 -> 9.7518673 | CA7: =BW7*M7 -> 94.43077 | CB7: =BW7*N7 -> 0.044915134 | CF7: =CH7*I7 -> 164.15826 | CH7: 46.708247 | CI7: =CH7*J7 -> 6.6495559 | CJ7: =CH7*K7 -> 0.2713014 | CK7: =CH7*L7 -> 4.467836 | CL7: =CH7*M7 -> 43.263632 | CM7: =CH7*N7 -> 0.020577951
A8: Roots and tubers | B8: 32.4 | C8: 1.6 | D8: 29.1 (1.4) | E8: 1.5 (0.1) | F8: =B8/I8 -> 14.959261 | G8: =F8*J8 -> 0.31062466 | I8: ='nutrient content'!G37/100 -> 2.1658824 | J8: ='nutrient content'!H37/100 -> 0.020764706 | K8: =AVERAGE(enviro!R281,enviro!R252) -> 0.0014733495 | L8: =AVERAGE(enviro!S281,enviro!S252) -> 0.014826503 | M8: =AVERAGE(enviro!T281,enviro!T252) -> 0.59340217 | N8: =AVERAGE(enviro!U281,enviro!U252) -> 0.0005814204 | O8: average of sweet potato and potato | U8: =B8 -> 32.4 | W8: =U8/I8 -> 14.959261 | X8: =W8*J8 -> 0.31062466 | Y8: =$W8*K8 -> 0.02204022 | Z8: =$W8*L8 -> 0.22179353 | AA8: =$W8*M8 -> 8.876858 | AB8: =$W8*N8 -> 0.0086976196 | AE8: 0 | AG8: =AE8/I8 -> 0 | AH8: =AG8*J8 -> 0 | AI8: =$AG8*K8 -> 0 | AJ8: =$AG8*L8 -> 0 | AK8: =$AG8*M8 -> 0 | AL8: =$AG8*N8 -> 0 | AO8: =AQ8*I8 -> 47.487442 | AQ8: 21.925218 | AR8: =AQ8*J8 -> 0.4552707 | AS8: =AQ8*K8 -> 0.032303509 | AT8: =AQ8*L8 -> 0.32507431 | AU8: =AQ8*M8 -> 13.010472 | AV8: =AQ8*N8 -> 0.012747769 | AY8: =BA8*I8 -> 64.149611 | BA8: 29.618235 | BB8: =BA8*J8 -> 0.61501393 | BC8: =BA8*K8 -> 0.043638011 | BD8: =BA8*L8 -> 0.43913484 | BE8: =BA8*M8 -> 17.575524 | BF8: =BA8*N8 -> 0.017220646 | BJ8: =BL8*I8 -> 57.786711 | BL8: 26.680448 | BM8: =BL8*J8 -> 0.55401165 | BN8: =BL8*K8 -> 0.039309625 | BO8: =BL8*L8 -> 0.39557774 | BP8: =BL8*M8 -> 15.832236 | BQ8: =BL8*N8 -> 0.015512557 | BU8: =BW8*I8 -> 65.327437 | BW8: 30.162043 | BX8: =BW8*J8 -> 0.62630595 | BY8: =BW8*K8 -> 0.044439231 | BZ8: =BW8*L8 -> 0.44719762 | CA8: =BW8*M8 -> 17.898222 | CB8: =BW8*N8 -> 0.017536827 | CF8: =CH8*I8 -> 33.07318 | CH8: 15.270072 | CI8: =CH8*J8 -> 0.31707856 | CJ8: =CH8*K8 -> 0.022498153 | CK8: =CH8*L8 -> 0.22640177 | CL8: =CH8*M8 -> 9.0612938 | CM8: =CH8*N8 -> 0.0088783313
A9: Eggs | B9: 33.3 | C9: 1.7 | D9: 33.3 (1.6) | E9: 1.7 (0.1) | F9: =B9/I9 -> 15.095195 | G9: =F9*J9 -> 2.7171351 | I9: ='nutrient content'!B208/100 -> 2.206 | J9: ='nutrient content'!C208/100 -> 0.18 | K9: =enviro!AD9 -> 0.0040165275 | L9: =enviro!AE9 -> 0.032725331 | M9: =enviro!AF9 -> 1.033 | N9: =enviro!AG9 -> 0.0020392735 | U9: =B9 -> 33.3 | W9: =U9/I9 -> 15.095195 | X9: =W9*J9 -> 2.7171351 | Y9: =$W9*K9 -> 0.060630266 | Z9: =$W9*L9 -> 0.49399525 | AA9: =$W9*M9 -> 15.593336 | AB9: =$W9*N9 -> 0.030783231 | AE9: 0 | AG9: =AE9/I9 -> 0 | AH9: =AG9*J9 -> 0 | AI9: =$AG9*K9 -> 0 | AJ9: =$AG9*L9 -> 0 | AK9: =$AG9*M9 -> 0 | AL9: =$AG9*N9 -> 0 | AO9: =AQ9*I9 -> 46.142925 | AQ9: 20.917011 | AR9: =AQ9*J9 -> 3.7650619 | AS9: =AQ9*K9 -> 0.084013749 | AT9: =AQ9*L9 -> 0.6845161 | AU9: =AQ9*M9 -> 21.607272 | AV9: =AQ9*N9 -> 0.042655505 | AY9: =BA9*I9 -> 81.849755 | BA9: 37.103243 | BB9: =BA9*J9 -> 6.6785838 | BC9: =BA9*K9 -> 0.1490262 | BD9: =BA9*L9 -> 1.2142159 | BE9: =BA9*M9 -> 38.32765 | BF9: =BA9*N9 -> 0.075663661 | BJ9: =BL9*I9 -> 118.00972 | BL9: 53.494888 | BM9: =BL9*J9 -> 9.6290799 | BN9: =BL9*K9 -> 0.21486369 | BO9: =BL9*L9 -> 1.7506379 | BP9: =BL9*M9 -> 55.26022 | BQ9: =BL9*N9 -> 0.10909071 | BU9: =BW9*I9 -> 81.622 | BW9: 37 | BX9: =BW9*J9 -> 6.66 | BY9: =BW9*K9 -> 0.14861152 | BZ9: =BW9*L9 -> 1.2108373 | CA9: =BW9*M9 -> 38.221 | CB9: =BW9*N9 -> 0.075453119 | CF9: =CH9*I9 -> 139.61284 | CH9: 63.28778 | CI9: =CH9*J9 -> 11.3918 | CJ9: =CH9*K9 -> 0.25419711 | CK9: =CH9*L9 -> 2.0711136 | CL9: =CH9*M9 -> 65.376277 | CM9: =CH9*N9 -> 0.12906109
A10: Pasta | B10: 38.4 | C10: 1.9 | D10: 35.8 (2.9) | E10: 1.8 (0.2) | F10: =B10/I10 -> 10.926022 | G10: =F10*J10 -> 1.5554682 | I10: ='nutrient content'!B44/100 -> 3.5145455 | J10: ='nutrient content'!C44/100 -> 0.14236364 | K10: =enviro!AD12 -> 0.0078441205 | L10: =enviro!AE12 -> 0.14199297 | M10: =enviro!AF12 -> 1.6622894 | N10: =enviro!AG12 -> 0.0011137228 | O10: assumed refined grains | U10: =B10 -> 38.4 | W10: =U10/I10 -> 10.926022 | X10: =W10*J10 -> 1.5554682 | Y10: =$W10*K10 -> 0.085705031 | Z10: =$W10*L10 -> 1.5514183 | AA10: =$W10*M10 -> 18.16221 | AB10: =$W10*N10 -> 0.01216856 | AE10: 0 | AG10: =AE10/I10 -> 0 | AH10: =AG10*J10 -> 0 | AI10: =$AG10*K10 -> 0 | AJ10: =$AG10*L10 -> 0 | AK10: =$AG10*M10 -> 0 | AL10: =$AG10*N10 -> 0 | AO10: =AQ10*I10 -> 59.449641 | AQ10: 16.915314 | AR10: =AQ10*J10 -> 2.4081256 | AS10: =AQ10*K10 -> 0.13268576 | AT10: =AQ10*L10 -> 2.4018557 | AU10: =AQ10*M10 -> 28.118147 | AV10: =AQ10*N10 -> 0.018838971 | AY10: =BA10*I10 -> 138.51128 | BA10: 39.410867 | BB10: =BA10*J10 -> 5.6106744 | BC10: =BA10*K10 -> 0.30914359 | BD10: =BA10*L10 -> 5.5960661 | BE10: =BA10*M10 -> 65.512266 | BF10: =BA10*N10 -> 0.043892782 | BJ10: =BL10*I10 -> 167.75127 | BL10: 47.730573 | BM10: =BL10*J10 -> 6.7950979 | BN10: =BL10*K10 -> 0.37440436 | BO10: =BL10*L10 -> 6.7774058 | BP10: =BL10*M10 -> 79.342024 | BQ10: =BL10*N10 -> 0.053158627 | BU10: =BW10*I10 -> 337.42895 | BW10: 96.009272 | BX10: =BW10*J10 -> 13.668229 | BY10: =BW10*K10 -> 0.7531083 | BZ10: =BW10*L10 -> 13.632642 | CA10: =BW10*M10 -> 159.59519 | CB10: =BW10*N10 -> 0.10692772 | CF10: =CH10*I10 -> 164.15826 | CH10: 46.708247 | CI10: =CH10*J10 -> 6.6495559 | CJ10: =CH10*K10 -> 0.36638512 | CK10: =CH10*L10 -> 6.6322427 | CL10: =CH10*M10 -> 77.642623 | CM10: =CH10*N10 -> 0.05202004
A11: Legumes | B11: 16.6 | C11: 0.8 | D11: 15.2 (1.6) | E11: 0.7 (0.1) | F11: =B11/I11 -> 4.7666906 | G11: =F11*J11 -> 1.1511558 | I11: ='nutrient content'!B74/100 -> 3.4825 | J11: ='nutrient content'!C74/100 -> 0.2415 | K11: =enviro!AD14 -> 0.005444405 | L11: =enviro!AE14 -> 0.036540476 | M11: =enviro!AF14 -> 1.0084882 | N11: =enviro!AG14 -> 0.00062807097 | U11: =B11 -> 16.6 | W11: =U11/I11 -> 4.7666906 | X11: =W11*J11 -> 1.1511558 | Y11: =$W11*K11 -> 0.025951794 | Z11: =$W11*L11 -> 0.17417714 | AA11: =$W11*M11 -> 4.8071512 | AB11: =$W11*N11 -> 0.00299382 | AE11: 0 | AG11: =AE11/I11 -> 0 | AH11: =AG11*J11 -> 0 | AI11: =$AG11*K11 -> 0 | AJ11: =$AG11*L11 -> 0 | AK11: =$AG11*M11 -> 0 | AL11: =$AG11*N11 -> 0 | AO11: =AQ11*I11 -> 36.335328 | AQ11: 10.433691 | AR11: =AQ11*J11 -> 2.5197363 | AS11: =AQ11*K11 -> 0.056805238 | AT11: =AQ11*L11 -> 0.38125202 | AU11: =AQ11*M11 -> 10.522254 | AV11: =AQ11*N11 -> 0.0065530983 | AY11: =BA11*I11 -> 130.56743 | BA11: 37.492442 | BB11: =BA11*J11 -> 9.0544248 | BC11: =BA11*K11 -> 0.20412404 | BD11: =BA11*L11 -> 1.3699917 | BE11: =BA11*M11 -> 37.810685 | BF11: =BA11*N11 -> 0.023547915 | BJ11: =BL11*I11 -> 202.08618 | BL11: 58.029055 | BM11: =BL11*J11 -> 14.014017 | BN11: =BL11*K11 -> 0.31593368 | BO11: =BL11*L11 -> 2.1204093 | BP11: =BL11*M11 -> 58.521617 | BQ11: =BL11*N11 -> 0.036446365 | BU11: =BW11*I11 -> 337.00152 | BW11: 96.77 | BX11: =BW11*J11 -> 23.369955 | BY11: =BW11*K11 -> 0.52685507 | BZ11: =BW11*L11 -> 3.5360218 | CA11: =BW11*M11 -> 97.591403 | CB11: =BW11*N11 -> 0.060778428 | CF11: =CH11*I11 -> 233.322 | CH11: 66.998422 | CI11: =CH11*J11 -> 16.180119 | CJ11: =CH11*K11 -> 0.36476654 | CK11: =CH11*L11 -> 2.4481542 | CL11: =CH11*M11 -> 67.567118 | CM11: =CH11*N11 -> 0.042079764
A12: Fish and sea food | B12: 13.8 | C12: 0.7 | D12: 13.8 (1.1) | E12: 0.7 (0.1) | F12: =B12/I12 -> 9.4174994 | G12: =F12*J12 -> 2.0311528 | I12: ='nutrient content'!B238/100 -> 1.4653571 | J12: ='nutrient content'!C238/100 -> 0.21567857 | K12: =enviro!AD10 -> 0.0022558557 | L12: =enviro!AE10 -> 9.6747447e-05 | M12: =enviro!AF10 -> 0.48611712 | N12: =enviro!AG10 -> 0.0092764998 | U12: =B12 -> 13.8 | W12: =U12/I12 -> 9.4174994 | X12: =W12*J12 -> 2.0311528 | Y12: =$W12*K12 -> 0.02124452 | Z12: =$W12*L12 -> 0.00091111903 | AA12: =$W12*M12 -> 4.5780077 | AB12: =$W12*N12 -> 0.087361431 | AE12: 0 | AG12: =AE12/I12 -> 0 | AH12: =AG12*J12 -> 0 | AI12: =$AG12*K12 -> 0 | AJ12: =$AG12*L12 -> 0 | AK12: =$AG12*M12 -> 0 | AL12: =$AG12*N12 -> 0 | AO12: =AQ12*I12 -> 22.233947 | AQ12: 15.173057 | AR12: =AQ12*J12 -> 3.2725032 | AS12: =AQ12*K12 -> 0.034228227 | AT12: =AQ12*L12 -> 0.0014679545 | AU12: =AQ12*M12 -> 7.3758827 | AV12: =AQ12*N12 -> 0.14075286 | AY12: =BA12*I12 -> 41.762155 | BA12: 28.499643 | BB12: =BA12*J12 -> 6.1467623 | BC12: =BA12*K12 -> 0.064291083 | BD12: =BA12*L12 -> 0.0027572677 | BE12: =BA12*M12 -> 13.854164 | BF12: =BA12*N12 -> 0.26437693 | BJ12: =BL12*I12 -> 75.58073 | BL12: 51.578368 | BM12: =BL12*J12 -> 11.124349 | BN12: =BL12*K12 -> 0.11635336 | BO12: =BL12*L12 -> 0.0049900755 | BP12: =BL12*M12 -> 25.073128 | BQ12: =BL12*N12 -> 0.47846672 | BU12: =BW12*I12 -> 54.218214 | BW12: 37 | BX12: =BW12*J12 -> 7.9801071 | BY12: =BW12*K12 -> 0.083466662 | BZ12: =BW12*L12 -> 0.0035796556 | CA12: =BW12*M12 -> 17.986333 | CB12: =BW12*N12 -> 0.34323049 | CF12: =CH12*I12 -> 90.812233 | CH12: 61.972764 | CI12: =CH12*J12 -> 13.366197 | CJ12: =CH12*K12 -> 0.13980162 | CK12: =CH12*L12 -> 0.0059957068 | CL12: =CH12*M12 -> 30.126022 | CM12: =CH12*N12 -> 0.57489033
A13: Vegetables | B13: 17.3 | C13: 0.9 | D13: 13.0 (0.9) | E13: 0.7 (0.0) | F13: =B13/I13 -> 32.67018 | G13: =F13*J13 -> 0.77268775 | I13: ='nutrient content'!B125/100 -> 0.52953488 | J13: ='nutrient content'!C125/100 -> 0.023651163 | K13: =enviro!AD22 -> 0.0012712095 | L13: =enviro!AE22 -> 0.022446556 | M13: =enviro!AF22 -> 1.4468796 | N13: =enviro!AG22 -> 0.00069335678 | U13: =B13 -> 17.3 | W13: =U13/I13 -> 32.67018 | X13: =W13*J13 -> 0.77268775 | Y13: =$W13*K13 -> 0.041530643 | Z13: =$W13*L13 -> 0.73333303 | AA13: =$W13*M13 -> 47.269816 | AB13: =$W13*N13 -> 0.022652091 | AE13: 0 | AG13: =AE13/I13 -> 0 | AH13: =AG13*J13 -> 0 | AI13: =$AG13*K13 -> 0 | AJ13: =$AG13*L13 -> 0 | AK13: =$AG13*M13 -> 0 | AL13: =$AG13*N13 -> 0 | AO13: =AQ13*I13 -> 20.716725 | AQ13: 39.122494 | AR13: =AQ13*J13 -> 0.92529248 | AS13: =AQ13*K13 -> 0.049732885 | AT13: =AQ13*L13 -> 0.87816526 | AU13: =AQ13*M13 -> 56.605537 | AV13: =AQ13*N13 -> 0.027125847 | AY13: =BA13*I13 -> 20.724406 | BA13: 39.136998 | BB13: =BA13*J13 -> 0.92563551 | BC13: =BA13*K13 -> 0.049751323 | BD13: =BA13*L13 -> 0.87849082 | BE13: =BA13*M13 -> 56.626523 | BF13: =BA13*N13 -> 0.027135903 | BJ13: =BL13*I13 -> 20.765143 | BL13: 39.213928 | BM13: =BL13*J13 -> 0.92745501 | BN13: =BL13*K13 -> 0.049849118 | BO13: =BL13*L13 -> 0.88021764 | BP13: =BL13*M13 -> 56.737832 | BQ13: =BL13*N13 -> 0.027189243 | BU13: =BW13*I13 -> 23.763604 | BW13: 44.876371 | BX13: =BW13*J13 -> 1.0613784 | BY13: =BW13*K13 -> 0.057047268 | BZ13: =BW13*L13 -> 1.00732 | CA13: =BW13*M13 -> 64.930704 | CB13: =BW13*N13 -> 0.031115336 | CF13: =CH13*I13 -> 5.2953488 | CH13: 10 | CI13: =CH13*J13 -> 0.23651163 | CJ13: =CH13*K13 -> 0.012712095 | CK13: =CH13*L13 -> 0.22446556 | CL13: =CH13*M13 -> 14.468796 | CM13: =CH13*N13 -> 0.0069335678
A14: Other unprocessed or minimally processed foods | B14: 46 | C14: 2.2 | D14: 43.0 (3.2) | E14: 2.1 (0.2) | F14: =B14/I14 -> 21.741411 | G14: =F14*J14 -> 2.7590287 | I14: =AVERAGE(I4:I13) -> 2.115778 | J14: =AVERAGE(J4:J13) -> 0.126902 | K14: =AVERAGE(K4:K13) -> 0.022839579 | L14: =AVERAGE(L4:L13) -> 0.072825954 | M14: =AVERAGE(M4:M13) -> 2.5283103 | N14: =AVERAGE(N4:N13) -> 0.003292751 | O14: assumed average of the category | U14: =B14 -> 46 | W14: =U14/I14 -> 21.741411 | X14: =W14*J14 -> 2.7590287 | Y14: =$W14*K14 -> 0.49656468 | Z14: =$W14*L14 -> 1.583339 | AA14: =$W14*M14 -> 54.969035 | AB14: =$W14*N14 -> 0.071589054 | AE14: 0 | AG14: =AE14/I14 -> 0 | AH14: =AG14*J14 -> 0 | AI14: =$AG14*K14 -> 0 | AJ14: =$AG14*L14 -> 0 | AK14: =$AG14*M14 -> 0 | AL14: =$AG14*N14 -> 0 | AO14: =AQ14*I14 -> 58.900173 | AQ14: 27.838541 | AR14: =AQ14*J14 -> 3.5327666 | AS14: =AQ14*K14 -> 0.63582056 | AT14: =AQ14*L14 -> 2.0273683 | AU14: =AQ14*M14 -> 70.384471 | AV14: =AQ14*N14 -> 0.091665385 | AY14: =BA14*I14 -> 86.653966 | BA14: 40.956077 | BB14: =BA14*J14 -> 5.1974082 | BC14: =BA14*K14 -> 0.93541955 | BD14: =BA14*L14 -> 2.9826654 | BE14: =BA14*M14 -> 103.54967 | BF14: =BA14*N14 -> 0.13485816 | BJ14: =BL14*I14 -> 108.9603 | BL14: 51.498929 | BM14: =BL14*J14 -> 6.5353172 | BN14: =BL14*K14 -> 1.1762139 | BO14: =BL14*L14 -> 3.7504587 | BP14: =BL14*M14 -> 130.20527 | BQ14: =BL14*N14 -> 0.16957315 | BU14: =BW14*I14 -> 208.74504 | BW14: 98.661128 | BX14: =BW14*J14 -> 12.520295 | BY14: =BW14*K14 -> 2.2533786 | BZ14: =BW14*L14 -> 7.1850908 | CA14: =BW14*M14 -> 249.44595 | CB14: =BW14*N14 -> 0.32486653 | CF14: =CH14*I14 -> 79.34521 | CH14: 37.501671 | CI14: =CH14*J14 -> 4.7590371 | CJ14: =CH14*K14 -> 0.85652237 | CK14: =CH14*L14 -> 2.731095 | CL14: =CH14*M14 -> 94.815861 | CM14: =CH14*N14 -> 0.12348366
A15: Processed culinary ingredients | B15: 108.3 | C15: 5.2 | D15: 108.3 (3.1) | E15: 5.2 (0.1) | G15: =F15*J15 -> 0 | X15: =W15*J15 -> 0 | Y15: =$W15*K15 -> 0 | Z15: =$W15*L15 -> 0 | AA15: =$W15*M15 -> 0 | AB15: =$W15*N15 -> 0 | AE15: 0 | AH15: =AG15*J15 -> 0 | AI15: =$AG15*K15 -> 0 | AJ15: =$AG15*L15 -> 0 | AK15: =$AG15*M15 -> 0 | AL15: =$AG15*N15 -> 0 | AO15: =AQ15*I15 -> 0 | AY15: =BA15*I15 -> 0 | BB15: =BA15*J15 -> 0 | BC15: =BA15*K15 -> 0 | BD15: =BA15*L15 -> 0 | BE15: =BA15*M15 -> 0 | BF15: =BA15*N15 -> 0 | BJ15: =BL15*I15 -> 0 | BM15: =BL15*J15 -> 0 | BN15: =BL15*K15 -> 0 | BO15: =BL15*L15 -> 0 | BP15: =BL15*M15 -> 0 | BQ15: =BL15*N15 -> 0 | BU15: =BW15*I15 -> 0 | BX15: =BW15*J15 -> 0 | BY15: =BW15*K15 -> 0 | BZ15: =BW15*L15 -> 0 | CA15: =BW15*M15 -> 0 | CB15: =BW15*N15 -> 0 | CF15: =CH15*I15 -> 0 | CI15: =CH15*J15 -> 0 | CJ15: =CH15*K15 -> 0 | CK15: =CH15*L15 -> 0 | CL15: =CH15*M15 -> 0 | CM15: =CH15*N15 -> 0
A16: Table sugar | B16: 21 | C16: 1 | D16: 21.0 (1.0) | E16: 1.0 (0.1) | F16: =B16/I16 -> 5.4263566 | G16: =F16*J16 -> 0 | I16: ='nutrient content'!G43/100 -> 3.87 | J16: ='nutrient content'!H43/100 -> 0 | K16: =enviro!R248 -> 0.00030104467 | L16: =enviro!S248 -> 0.0125 | M16: =enviro!T248 -> 1.023 | N16: =enviro!U248 -> 0.0004008408 | O16: assumed as sugar, enviro row 248 | U16: =B16*$U$46 -> 32.424 | W16: =U16/I16 -> 8.3782946 | X16: =W16*J16 -> 0 | Y16: =$W16*K16 -> 0.0025222409 | Z16: =$W16*L16 -> 0.10472868 | AA16: =$W16*M16 -> 8.5709953 | AB16: =$W16*N16 -> 0.0033583623 | AE16: 0 | AG16: =AE16/I16 -> 0 | AH16: =AG16*J16 -> 0 | AI16: =$AG16*K16 -> 0 | AJ16: =$AG16*L16 -> 0 | AK16: =$AG16*M16 -> 0 | AL16: =$AG16*N16 -> 0 | AO16: =AQ16*I16 -> 279.26798 | AQ16: 72.162268 | AR16: =AQ16*J16 -> 0 | AS16: =AQ16*K16 -> 0.021724066 | AT16: =AQ16*L16 -> 0.90202835 | AU16: =AQ16*M16 -> 73.822 | AV16: =AQ16*N16 -> 0.028925581 | AY16: =BA16*I16 -> 116.06455 | BA16: 29.99084 | BB16: =BA16*J16 -> 0 | BC16: =BA16*K16 -> 0.0090285826 | BD16: =BA16*L16 -> 0.3748855 | BE16: =BA16*M16 -> 30.68063 | BF16: =BA16*N16 -> 0.012021553 | BJ16: =BL16*I16 -> 79.027229 | BL16: 20.420473 | BM16: =BL16*J16 -> 0 | BN16: =BL16*K16 -> 0.0061474744 | BO16: =BL16*L16 -> 0.25525591 | BP16: =BL16*M16 -> 20.890143 | BQ16: =BL16*N16 -> 0.0081853586 | BU16: =BW16*I16 -> 59.7141 | BW16: 15.43 | BX16: =BW16*J16 -> 0 | BY16: =BW16*K16 -> 0.0046451192 | BZ16: =BW16*L16 -> 0.192875 | CA16: =BW16*M16 -> 15.78489 | CB16: =BW16*N16 -> 0.0061849736 | CF16: =CH16*I16 -> 77.169834 | CH16: 19.940525 | CI16: =CH16*J16 -> 0 | CJ16: =CH16*K16 -> 0.0060029889 | CK16: =CH16*L16 -> 0.24925657 | CL16: =CH16*M16 -> 20.399158 | CM16: =CH16*N16 -> 0.0079929763
A17: Plant oils | B17: 51.5 | C17: 2.4 | D17: 51.5 (2.4) | E17: 2.4 (0.1) | F17: =B17/I17 -> 5.9461193 | G17: =F17*J17 -> 0.0026427197 | I17: ='nutrient content'!B275/100 -> 8.6611111 | J17: ='nutrient content'!C275/100 -> 0.00044444444 | K17: =enviro!AD16 -> 0.016554871 | L17: =enviro!AE16 -> 0.51142133 | M17: =enviro!AF16 -> 7.8334208 | N17: =enviro!AG16 -> 0.0029773813 | U17: =B17 -> 51.5 | W17: =U17/I17 -> 5.9461193 | X17: =W17*J17 -> 0.0026427197 | Y17: =$W17*K17 -> 0.098437236 | Z17: =$W17*L17 -> 3.0409723 | AA17: =$W17*M17 -> 46.578455 | AB17: =$W17*N17 -> 0.017703864 | AE17: 0 | AG17: =AE17/I17 -> 0 | AH17: =AG17*J17 -> 0 | AI17: =$AG17*K17 -> 0 | AJ17: =$AG17*L17 -> 0 | AK17: =$AG17*M17 -> 0 | AL17: =$AG17*N17 -> 0 | AO17: =AQ17*I17 -> 852.81317 | AQ17: 98.464638 | AR17: =AQ17*J17 -> 0.043762061 | AS17: =AQ17*K17 -> 1.6300694 | AT17: =AQ17*L17 -> 50.356917 | AU17: =AQ17*M17 -> 771.31495 | AV17: =AQ17*N17 -> 0.29316677 | AY17: =BA17*I17 -> 527.55203 | BA17: 60.910434 | BB17: =BA17*J17 -> 0.027071304 | BC17: =BA17*K17 -> 1.0083644 | BD17: =BA17*L17 -> 31.150895 | BE17: =BA17*M17 -> 477.13706 | BF17: =BA17*N17 -> 0.18135358 | BJ17: =BL17*I17 -> 342.06687 | BL17: 39.494572 | BM17: =BL17*J17 -> 0.017553143 | BN17: =BL17*K17 -> 0.65382753 | BO17: =BL17*L17 -> 20.198367 | BP17: =BL17*M17 -> 309.3776 | BQ17: =BL17*N17 -> 0.1175904 | BU17: =BW17*I17 -> 188.54034 | BW17: 21.768609 | BX17: =BW17*J17 -> 0.0096749374 | BY17: =BW17*K17 -> 0.36037651 | BZ17: =BW17*L17 -> 11.132931 | CA17: =BW17*M17 -> 170.52268 | CB17: =BW17*N17 -> 0.064813449 | CF17: =CH17*I17 -> 386.4712 | CH17: 44.621434 | CI17: =CH17*J17 -> 0.019831749 | CJ17: =CH17*K17 -> 0.73870208 | CK17: =CH17*L17 -> 22.820353 | CL17: =CH17*M17 -> 349.53847 | CM17: =CH17*N17 -> 0.13285502
A18: Animal fats | B18: 34.6 | C18: 1.7 | D18: 34.6 (1.8) | E18: 1.7 (0.1) | F18: =B18/I18 -> 4.2430849 | G18: =F18*J18 -> 0.042430849 | I18: ='nutrient content'!B286/100 -> 8.1544444 | J18: ='nutrient content'!C286/100 -> 0.01 | K18: =enviro!AD2 -> 0.041260521 | L18: =enviro!AE2 -> 0.33634106 | M18: =enviro!AF2 -> 2.7368774 | N18: =enviro!AG2 -> 0.0067288236 | U18: =B18 -> 34.6 | W18: =U18/I18 -> 4.2430849 | X18: =W18*J18 -> 0.042430849 | Y18: =$W18*K18 -> 0.17507189 | Z18: =$W18*L18 -> 1.4271237 | AA18: =$W18*M18 -> 11.612803 | AB18: =$W18*N18 -> 0.02855097 | AE18: 0 | AG18: =AE18/I18 -> 0 | AH18: =AG18*J18 -> 0 | AI18: =$AG18*K18 -> 0 | AJ18: =$AG18*L18 -> 0 | AK18: =$AG18*M18 -> 0 | AL18: =$AG18*N18 -> 0 | AO18: =AQ18*I18 -> 448.01867 | AQ18: 54.941655 | AR18: =AQ18*J18 -> 0.54941655 | AS18: =AQ18*K18 -> 2.2669213 | AT18: =AQ18*L18 -> 18.479135 | AU18: =AQ18*M18 -> 150.36857 | AV18: =AQ18*N18 -> 0.3696927 | AY18: =BA18*I18 -> 459.96718 | BA18: 56.406931 | BB18: =BA18*J18 -> 0.56406931 | BC18: =BA18*K18 -> 2.3273793 | BD18: =BA18*L18 -> 18.971967 | BE18: =BA18*M18 -> 154.37885 | BF18: =BA18*N18 -> 0.37955228 | BJ18: =BL18*I18 -> 305.51891 | BL18: 37.466552 | BM18: =BL18*J18 -> 0.37466552 | BN18: =BL18*K18 -> 1.5458894 | BO18: =BL18*L18 -> 12.60154 | BP18: =BL18*M18 -> 102.54136 | BQ18: =BL18*N18 -> 0.25210582 | BU18: =BW18*I18 -> 167.21632 | BW18: 20.506157 | BX18: =BW18*J18 -> 0.20506157 | BY18: =BW18*K18 -> 0.84609472 | BZ18: =BW18*L18 -> 6.8970626 | CA18: =BW18*M18 -> 56.122838 | CB18: =BW18*N18 -> 0.13798231 | CF18: =CH18*I18 -> 393.68099 | CH18: 48.278088 | CI18: =CH18*J18 -> 0.48278088 | CJ18: =CH18*K18 -> 1.9919791 | CK18: =CH18*L18 -> 16.237903 | CL18: =CH18*M18 -> 132.13121 | CM18: =CH18*N18 -> 0.32485474
A19: Other processed culinary ingredients | B19: 1.2 | C19: 0.07 | D19: 1.3 (0.2) | E19: 0.1 (0.0) | G19: =F19*J19 -> 0 | U19: =B19 -> 1.2 | X19: =W19*J19 -> 0 | Y19: =$W19*K19 -> 0 | Z19: =$W19*L19 -> 0 | AA19: =$W19*M19 -> 0 | AB19: =$W19*N19 -> 0 | AE19: 0 | AH19: =AG19*J19 -> 0 | AI19: =$AG19*K19 -> 0 | AJ19: =$AG19*L19 -> 0 | AK19: =$AG19*M19 -> 0 | AL19: =$AG19*N19 -> 0 | AO19: =AQ19*I19 -> 0 | AR19: =AQ19*J19 -> 0 | AS19: =AQ19*K19 -> 0 | AT19: =AQ19*L19 -> 0 | AU19: =AQ19*M19 -> 0 | AV19: =AQ19*N19 -> 0 | AY19: =BA19*I19 -> 0 | BB19: =BA19*J19 -> 0 | BC19: =BA19*K19 -> 0 | BD19: =BA19*L19 -> 0 | BE19: =BA19*M19 -> 0 | BF19: =BA19*N19 -> 0 | BJ19: =BL19*I19 -> 0 | BM19: =BL19*J19 -> 0 | BN19: =BL19*K19 -> 0 | BO19: =BL19*L19 -> 0 | BP19: =BL19*M19 -> 0 | BQ19: =BL19*N19 -> 0 | BU19: =BW19*I19 -> 0 | BX19: =BW19*J19 -> 0 | BY19: =BW19*K19 -> 0 | BZ19: =BW19*L19 -> 0 | CA19: =BW19*M19 -> 0 | CB19: =BW19*N19 -> 0 | CF19: =CH19*I19 -> 0 | CI19: =CH19*J19 -> 0 | CJ19: =CH19*K19 -> 0 | CK19: =CH19*L19 -> 0 | CL19: =CH19*M19 -> 0 | CM19: =CH19*N19 -> 0
A20: Processed foods | B20: 197.1 | C20: 9 | D20: 299.7 (9.8) | E20: 13.7 (0.4) | G20: =F20*J20 -> 0 | X20: =W20*J20 -> 0 | Y20: =$W20*K20 -> 0 | Z20: =$W20*L20 -> 0 | AA20: =$W20*M20 -> 0 | AB20: =$W20*N20 -> 0 | AE20: 0 | AO20: =AQ20*I20 -> 0 | AR20: =AQ20*J20 -> 0 | AS20: =AQ20*K20 -> 0 | AT20: =AQ20*L20 -> 0 | AU20: =AQ20*M20 -> 0 | AV20: =AQ20*N20 -> 0 | AY20: =BA20*I20 -> 0 | BB20: =BA20*J20 -> 0 | BC20: =BA20*K20 -> 0 | BD20: =BA20*L20 -> 0 | BE20: =BA20*M20 -> 0 | BF20: =BA20*N20 -> 0 | BJ20: =BL20*I20 -> 0 | BM20: =BL20*J20 -> 0 | BN20: =BL20*K20 -> 0 | BO20: =BL20*L20 -> 0 | BP20: =BL20*M20 -> 0 | BQ20: =BL20*N20 -> 0 | BU20: =BW20*I20 -> 0 | BX20: =BW20*J20 -> 0 | BY20: =BW20*K20 -> 0 | BZ20: =BW20*L20 -> 0 | CA20: =BW20*M20 -> 0 | CB20: =BW20*N20 -> 0 | CF20: =CH20*I20 -> 0 | CI20: =CH20*J20 -> 0 | CJ20: =CH20*K20 -> 0 | CK20: =CH20*L20 -> 0 | CL20: =CH20*M20 -> 0 | CM20: =CH20*N20 -> 0
A21: Cheese | B21: 71.4 | C21: 3.3 | D21: 70.0 (3.9) | E21: 3.2 (0.2) | F21: =B21/I21 -> 41.331404 | G21: =F21*J21 -> 9.0722431 | I21: ='nutrient content'!L211/100 -> 1.7275 | J21: ='nutrient content'!M211/100 -> 0.2195 | K21: =AVERAGE(enviro!R34:'enviro'!R37) -> 0.022928135 | L21: =AVERAGE(enviro!S34:'enviro'!S37) -> 0.06741283 | M21: =AVERAGE(enviro!T34:'enviro'!T37) -> 11.415937 | N21: =AVERAGE(enviro!U34:'enviro'!U37) -> 0.0042290178 | O21: mean of enviro rows 34-37 | U21: =B21 -> 71.4 | W21: =U21/I21 -> 41.331404 | X21: =W21*J21 -> 9.0722431 | Y21: =$W21*K21 -> 0.94765199 | Z21: =$W21*L21 -> 2.7862669 | AA21: =$W21*M21 -> 471.83672 | AB21: =$W21*N21 -> 0.17479124 | AE21: 0 | AG21: =AE21/I21 -> 0 | AH21: =AG21*J21 -> 0 | AI21: =$AG21*K21 -> 0 | AJ21: =$AG21*L21 -> 0 | AK21: =$AG21*M21 -> 0 | AL21: =$AG21*N21 -> 0 | AO21: =AQ21*I21 -> 81.119126 | AQ21: 46.957526 | AR21: =AQ21*J21 -> 10.307177 | AS21: =AQ21*K21 -> 1.0766485 | AT21: =AQ21*L21 -> 3.1655397 | AU21: =AQ21*M21 -> 536.06418 | AV21: =AQ21*N21 -> 0.19858421 | AY21: =BA21*I21 -> 107.20818 | BA21: 62.059725 | BB21: =BA21*J21 -> 13.62211 | BC21: =BA21*K21 -> 1.4229137 | BD21: =BA21*L21 -> 4.1836217 | BE21: =BA21*M21 -> 708.46994 | BF21: =BA21*N21 -> 0.26245169 | BJ21: =BL21*I21 -> 145.96594 | BL21: 84.49548 | BM21: =BL21*J21 -> 18.546758 | BN21: =BL21*K21 -> 1.9373237 | BO21: =BL21*L21 -> 5.6960795 | BP21: =BL21*M21 -> 964.59512 | BQ21: =BL21*N21 -> 0.35733289 | BU21: =BW21*I21 -> 63.9175 | BW21: 37 | BX21: =BW21*J21 -> 8.1215 | BY21: =BW21*K21 -> 0.84834098 | BZ21: =BW21*L21 -> 2.4942747 | CA21: =BW21*M21 -> 422.38969 | CB21: =BW21*N21 -> 0.15647366 | CF21: =CH21*I21 -> 164.49676 | CH21: 95.222438 | CI21: =CH21*J21 -> 20.901325 | CJ21: =CH21*K21 -> 2.1832729 | CK21: =CH21*L21 -> 6.4192141 | CL21: =CH21*M21 -> 1087.0534 | CM21: =CH21*N21 -> 0.40269739
A22: Ham and other salted, smoked or canned meat or fish | B22: 18.5 | C22: 0.9 | D22: 18.5 (1.8) | E22: 0.9 (0.1) | F22: =B22/I22 -> 8.1713781 | G22: =F22*J22 -> 1.8712456 | I22: ='nutrient content'!L189/100 -> 2.264 | J22: ='nutrient content'!M189/100 -> 0.229 | K22: =enviro!AD19 -> 0.33861575 | L22: =enviro!AE19 -> 0.46502213 | M22: =enviro!AF19 -> 10.153495 | N22: =enviro!AG19 -> 0.019571896 | O22: assumed red and processed meat | U22: =B22 -> 18.5 | W22: =U22/I22 -> 8.1713781 | X22: =W22*J22 -> 1.8712456 | Y22: =$W22*K22 -> 2.7669573 | Z22: =$W22*L22 -> 3.7998716 | AA22: =$W22*M22 -> 82.96805 | AB22: =$W22*N22 -> 0.15992936 | AE22: 0 | AG22: =AE22/I22 -> 0 | AH22: =AG22*J22 -> 0 | AI22: =$AG22*K22 -> 0 | AJ22: =$AG22*L22 -> 0 | AK22: =$AG22*M22 -> 0 | AL22: =$AG22*N22 -> 0 | AO22: =AQ22*I22 -> 31.283278 | AQ22: 13.817702 | AR22: =AQ22*J22 -> 3.1642538 | AS22: =AQ22*K22 -> 4.6788916 | AT22: =AQ22*L22 -> 6.4255373 | AU22: =AQ22*M22 -> 140.29798 | AV22: =AQ22*N22 -> 0.27043863 | AY22: =BA22*I22 -> 74.047632 | BA22: 32.706551 | BB22: =BA22*J22 -> 7.4898003 | BC22: =BA22*K22 -> 11.074953 | BD22: =BA22*L22 -> 15.20927 | BE22: =BA22*M22 -> 332.08582 | BF22: =BA22*N22 -> 0.64012921 | BJ22: =BL22*I22 -> 124.62393 | BL22: 55.045908 | BM22: =BL22*J22 -> 12.605513 | BN22: =BL22*K22 -> 18.639411 | BO22: =BL22*L22 -> 25.597565 | BP22: =BL22*M22 -> 558.90837 | BQ22: =BL22*N22 -> 1.0773528 | BU22: =BW22*I22 -> 83.768 | BW22: 37 | BX22: =BW22*J22 -> 8.473 | BY22: =BW22*K22 -> 12.528783 | BZ22: =BW22*L22 -> 17.205819 | CA22: =BW22*M22 -> 375.67933 | CB22: =BW22*N22 -> 0.72416014 | CF22: =CH22*I22 -> 151.32075 | CH22: 66.837786 | CI22: =CH22*J22 -> 15.305853 | CJ22: =CH22*K22 -> 22.632327 | CK22: =CH22*L22 -> 31.081049 | CL22: =CH22*M22 -> 678.63716 | CM22: =CH22*N22 -> 1.3081422
A23: Vegetables and other plant foods preserved in brine | B23: 11.3 | C23: 0.56 | D23: 11.3 (0.6) | E23: 0.6 (0.0) | F23: =B23/I23 -> 21.339482 | G23: =F23*J23 -> 0.50470356 | I23: ='nutrient content'!B125/100 -> 0.52953488 | J23: ='nutrient content'!C125/100 -> 0.023651163 | K23: =enviro!AD22 -> 0.0012712095 | L23: =enviro!AE22 -> 0.022446556 | M23: =enviro!AF22 -> 1.4468796 | N23: =enviro!AG22 -> 0.00069335678 | O23: assumed vegetable | U23: =B23 -> 11.3 | W23: =U23/I23 -> 21.339482 | X23: =W23*J23 -> 0.50470356 | Y23: =$W23*K23 -> 0.027126951 | Z23: =$W23*L23 -> 0.47899787 | AA23: =$W23*M23 -> 30.87566 | AB23: =$W23*N23 -> 0.014795874 | AE23: 0 | AG23: =AE23/I23 -> 0 | AH23: =AG23*J23 -> 0 | AI23: =$AG23*K23 -> 0 | AJ23: =$AG23*L23 -> 0 | AK23: =$AG23*M23 -> 0 | AL23: =$AG23*N23 -> 0 | AO23: =AQ23*I23 -> 14.682707 | AQ23: 27.727553 | AR23: =AQ23*J23 -> 0.65578888 | AS23: =AQ23*K23 -> 0.035247529 | AT23: =AQ23*L23 -> 0.62238808 | AU23: =AQ23*M23 -> 40.11843 | AV23: =AQ23*N23 -> 0.019225087 | AY23: =BA23*I23 -> 14.646735 | BA23: 27.659623 | BB23: =BA23*J23 -> 0.65418226 | BC23: =BA23*K23 -> 0.035161175 | BD23: =BA23*L23 -> 0.62086329 | BE23: =BA23*M23 -> 40.020144 | BF23: =BA23*N23 -> 0.019177987 | BJ23: =BL23*I23 -> 14.743014 | BL23: 27.84144 | BM23: =BL23*J23 -> 0.65848244 | BN23: =BL23*K23 -> 0.035392303 | BO23: =BL23*L23 -> 0.62494445 | BP23: =BL23*M23 -> 40.283211 | BQ23: =BL23*N23 -> 0.019304051 | BU23: =BW23*I23 -> 17.763974 | BW23: 33.546371 | BX23: =BW23*J23 -> 0.79341068 | BY23: =BW23*K23 -> 0.042644465 | BZ23: =BW23*L23 -> 0.7530005 | CA23: =BW23*M23 -> 48.537559 | CB23: =BW23*N23 -> 0.023259604 | CF23: =CH23*I23 -> 5.2953488 | CH23: 10 | CI23: =CH23*J23 -> 0.23651163 | CJ23: =CH23*K23 -> 0.012712095 | CK23: =CH23*L23 -> 0.22446556 | CL23: =CH23*M23 -> 14.468796 | CM23: =CH23*N23 -> 0.0069335678
A24: Other processed foods | B24: 95.8 | C24: 4.3 | D24: 199.9 (7.0) | E24: 9.0 (0.3) | F24: =B24/I24 -> 63.569516 | G24: =F24*J24 -> 10.004807 | I24: =AVERAGE(I21:I23) -> 1.5070116 | J24: =AVERAGE(J21:J23) -> 0.15738372 | K24: =AVERAGE(K21:K23) -> 0.12093836 | L24: =AVERAGE(L21:L23) -> 0.1849605 | M24: =AVERAGE(M21:M23) -> 7.6721042 | N24: =AVERAGE(N21:N23) -> 0.0081647568 | O24: assumed as average of the category | U24: =B24 -> 95.8 | W24: =U24/I24 -> 63.569516 | X24: =W24*J24 -> 10.004807 | Y24: =$W24*K24 -> 7.6879933 | Z24: =$W24*L24 -> 11.75785 | AA24: =$W24*M24 -> 487.71195 | AB24: =$W24*N24 -> 0.51902964 | AE24: 0 | AG24: =AE24/I24 -> 0 | AH24: =AG24*J24 -> 0 | AI24: =$AG24*K24 -> 0 | AJ24: =$AG24*L24 -> 0 | AK24: =$AG24*M24 -> 0 | AL24: =$AG24*N24 -> 0 | AO24: =AQ24*I24 -> 104.73309 | AQ24: 69.497201 | AR24: =AQ24*J24 -> 10.937728 | AS24: =AQ24*K24 -> 8.4048778 | AT24: =AQ24*L24 -> 12.854237 | AU24: =AQ24*M24 -> 533.18977 | AV24: =AQ24*N24 -> 0.56742774 | AY24: =BA24*I24 -> 120.92912 | BA24: 80.24432 | BB24: =BA24*J24 -> 12.62915 | BC24: =BA24*K24 -> 9.7046168 | BD24: =BA24*L24 -> 14.84203 | BE24: =BA24*M24 -> 615.64279 | BF24: =BA24*N24 -> 0.65517536 | BJ24: =BL24*I24 -> 144.58043 | BL24: 95.938496 | BM24: =BL24*J24 -> 15.099157 | BN24: =BL24*K24 -> 11.602645 | BO24: =BL24*L24 -> 17.744833 | BP24: =BL24*M24 -> 736.05013 | BQ24: =BL24*N24 -> 0.78331448 | BU24: =BW24*I24 -> 234.4458 | BW24: 155.57 | BX24: =BW24*J24 -> 24.484185 | BY24: =BW24*K24 -> 18.814381 | BZ24: =BW24*L24 -> 28.774306 | CA24: =BW24*M24 -> 1193.5492 | CB24: =BW24*N24 -> 1.2701912 | CF24: =CH24*I24 -> 61.021939 | CH24: 40.492016 | CI24: =CH24*J24 -> 6.3727842 | CJ24: =CH24*K24 -> 4.8970382 | CK24: =CH24*L24 -> 7.4894237 | CL24: =CH24*M24 -> 310.65897 | CM24: =CH24*N24 -> 0.33060746
A25: Ultraprocessed foods | B25: 1232.8 | C25: 58.2 | D25: 1127.3 (16.0) | E25: 53.4 (0.8) | G25: =F25*J25 -> 0 | X25: =W25*J25 -> 0 | Y25: =$W25*K25 -> 0 | Z25: =$W25*L25 -> 0 | AA25: =$W25*M25 -> 0 | AB25: =$W25*N25 -> 0 | AE25: =U25 -> 0 | AS25: =AQ25*K25 -> 0 | AT25: =AQ25*L25 -> 0 | AU25: =AQ25*M25 -> 0 | AV25: =AQ25*N25 -> 0 | AY25: =AE25*AY67 -> 0 | BC25: =BA25*K25 -> 0 | BD25: =BA25*L25 -> 0 | BE25: =BA25*M25 -> 0 | BF25: =BA25*N25 -> 0 | BJ25: =BL25*I25 -> 0 | BL25: 0 | BM25: =BL25*J25 -> 0 | BN25: =BL25*K25 -> 0 | BO25: =BL25*L25 -> 0 | BP25: =BL25*M25 -> 0 | BQ25: =BL25*N25 -> 0 | BU25: =BW25*I25 -> 0 | BW25: 0 | BX25: =BW25*U25 -> 0 | BY25: =BW25*V25 -> 0 | BZ25: =BW25*W25 -> 0 | CA25: =BW25*X25 -> 0 | CB25: =BW25*Y25 -> 0 | CF25: =CH25*AE25 -> 0 | CH25: 0 | CI25: =CH25*J25 -> 0 | CJ25: =CH25*AG25 -> 0 | CK25: =CH25*AH25 -> 0 | CL25: =CH25*AI25 -> 0 | CM25: =CH25*AJ25 -> 0
A26: Breads | B26: 207.4 | C26: 10 | D26: 149.1 (5.2) | E26: 7.4 (0.3) | F26: =B26/I26 -> 59.011899 | G26: =F26*J26 -> 8.4011485 | I26: ='nutrient content'!B44/100 -> 3.5145455 | J26: ='nutrient content'!C44/100 -> 0.14236364 | K26: =enviro!AD12 -> 0.0078441205 | L26: =enviro!AE12 -> 0.14199297 | M26: =enviro!AF12 -> 1.6622894 | N26: =enviro!AG12 -> 0.0011137228 | O26: assumed refined grains | U26: =B26 -> 207.4 | W26: =U26/I26 -> 59.011899 | X26: =W26*J26 -> 8.4011485 | Y26: =$W26*K26 -> 0.46289645 | Z26: =$W26*L26 -> 8.3792747 | AA26: =$W26*M26 -> 98.094852 | AB26: =$W26*N26 -> 0.065722897 | AE26: =U26 -> 207.4 | AG26: =AE26/I26 -> 59.011899 | AH26: =AG26*J26 -> 8.4011485 | AI26: =$AG26*K26 -> 0.46289645 | AJ26: =$AG26*L26 -> 8.3792747 | AK26: =$AG26*M26 -> 98.094852 | AL26: =$AG26*N26 -> 0.065722897 | AO26: 0 | AQ26: =AO26/I26 -> 0 | AR26: 0 | AS26: =AQ26*K26 -> 0 | AT26: =AQ26*L26 -> 0 | AU26: =AQ26*M26 -> 0 | AV26: =AQ26*N26 -> 0 | AY26: 0 | BA26: =AY26/I26 -> 0 | BB26: 0 | BC26: =BA26*K26 -> 0 | BD26: =BA26*L26 -> 0 | BE26: =BA26*M26 -> 0 | BF26: =BA26*N26 -> 0 | BJ26: 0 | BL26: =BJ26/I26 -> 0 | BM26: =BL26*J26 -> 0 | BN26: =BL26*K26 -> 0 | BO26: =BL26*L26 -> 0 | BP26: =BL26*M26 -> 0 | BQ26: =BL26*N26 -> 0 | BU26: =BW26*I26 -> 0 | BW26: 0 | BX26: =BW26*U26 -> 0 | BY26: =BW26*V26 -> 0 | BZ26: =BW26*W26 -> 0 | CA26: =BW26*X26 -> 0 | CB26: =BW26*Y26 -> 0 | CF26: 0 | CH26: 0 | CI26: =CH26*J26 -> 0 | CJ26: =CH26*AG26 -> 0 | CK26: =CH26*AH26 -> 0 | CL26: =CH26*AI26 -> 0 | CM26: =CH26*AJ26 -> 0
A27: Cakes, cookies and pies | B27: 128.8 | C27: 5.8 | D27: 128.8 (3.8) | E27: 5.8 (0.2) | F27: =B27/I27 -> 39.108712 | G27: =F27*J27 -> 2.8185925 | I27: =AVERAGE('nutrient content'!B44,'nutrient content'!B60)/100 -> 3.2933838 | J27: =AVERAGE('nutrient content'!C44,'nutrient content'!C60)/100 -> 0.072070707 | K27: =AVERAGE(enviro!AD12,enviro!AD20) -> 0.018451704 | L27: =AVERAGE(enviro!AE12,enviro!AE20) -> 0.11522772 | M27: =AVERAGE(enviro!AF12,enviro!AF20) -> 3.9250933 | N27: =AVERAGE(enviro!AG12,enviro!AG20) -> 0.001437584 | O27: assumed average of sweets and refined grains | U27: =B27*$U$46 -> 198.8672 | W27: =U27/I27 -> 60.383851 | X27: =W27*J27 -> 4.3519069 | Y27: =$W27*K27 -> 1.114185 | Z27: =$W27*L27 -> 6.9578936 | AA27: =$W27*M27 -> 237.01225 | AB27: =$W27*N27 -> 0.086806857 | AE27: =U27 -> 198.8672 | AG27: =AE27/I27 -> 60.383851 | AH27: =AG27*J27 -> 4.3519069 | AI27: =$AG27*K27 -> 1.114185 | AJ27: =$AG27*L27 -> 6.9578936 | AK27: =$AG27*M27 -> 237.01225 | AL27: =$AG27*N27 -> 0.086806857 | AO27: 0 | AQ27: =AO27/I27 -> 0 | AR27: 0 | AS27: =AQ27*K27 -> 0 | AT27: =AQ27*L27 -> 0 | AU27: =AQ27*M27 -> 0 | AV27: =AQ27*N27 -> 0 | AY27: 0 | BA27: =AY27/I27 -> 0 | BB27: 0 | BC27: =BA27*K27 -> 0 | BD27: =BA27*L27 -> 0 | BE27: =BA27*M27 -> 0 | BF27: =BA27*N27 -> 0 | BJ27: 0 | BL27: =BJ27/I27 -> 0 | BM27: =BL27*J27 -> 0 | BN27: =BL27*K27 -> 0 | BO27: =BL27*L27 -> 0 | BP27: =BL27*M27 -> 0 | BQ27: =BL27*N27 -> 0 | BU27: =BW27*I27 -> 0 | BW27: 0 | BX27: =BW27*U27 -> 0 | BY27: =BW27*V27 -> 0 | BZ27: =BW27*W27 -> 0 | CA27: =BW27*X27 -> 0 | CB27: =BW27*Y27 -> 0 | CF27: 0 | CH27: 0 | CI27: =CH27*J27 -> 0 | CJ27: =CH27*AG27 -> 0 | CK27: =CH27*AH27 -> 0 | CL27: =CH27*AI27 -> 0 | CM27: =CH27*AJ27 -> 0
A28: Reconstituted meat or fish products | B28: 121.9 | C28: 5.6 | D28: 121.9 (4.2) | E28: 5.6 (0.2) | F28: =B28/I28 -> 70.365682 | G28: =F28*J28 -> 13.51224 | I28: =AVERAGE('nutrient content'!B238,'nutrient content'!L194)/100 -> 1.7323786 | J28: =AVERAGE('nutrient content'!C238,'nutrient content'!M194)/100 -> 0.19202883 | K28: =AVERAGE(enviro!AD10,enviro!AD18,enviro!AD19) -> 0.11887542 | L28: =AVERAGE(enviro!AE10,enviro!AE18,enviro!AE19) -> 0.19783524 | M28: =AVERAGE(enviro!AF10,enviro!AF18,enviro!AF19) -> 4.7083998 | N28: =AVERAGE(enviro!AG10,enviro!AG18,enviro!AG19) -> 0.012212755 | O28: assumed as average of fish, poultry and red and processed meat | U28: =B28 -> 121.9 | W28: =U28/I28 -> 70.365682 | X28: =W28*J28 -> 13.51224 | Y28: =$W28*K28 -> 8.3647497 | Z28: =$W28*L28 -> 13.920812 | AA28: =$W28*M28 -> 331.30977 | AB28: =$W28*N28 -> 0.85935884 | AE28: =U28 -> 121.9 | AG28: =AE28/I28 -> 70.365682 | AH28: =AG28*J28 -> 13.51224 | AI28: =$AG28*K28 -> 8.3647497 | AJ28: =$AG28*L28 -> 13.920812 | AK28: =$AG28*M28 -> 331.30977 | AL28: =$AG28*N28 -> 0.85935884 | AO28: 0 | AQ28: =AO28/I28 -> 0 | AR28: 0 | AS28: =AQ28*K28 -> 0 | AT28: =AQ28*L28 -> 0 | AU28: =AQ28*M28 -> 0 | AV28: =AQ28*N28 -> 0 | AY28: 0 | BA28: =AY28/I28 -> 0 | BB28: 0 | BC28: =BA28*K28 -> 0 | BD28: =BA28*L28 -> 0 | BE28: =BA28*M28 -> 0 | BF28: =BA28*N28 -> 0 | BJ28: 0 | BL28: =BJ28/I28 -> 0 | BM28: =BL28*J28 -> 0 | BN28: =BL28*K28 -> 0 | BO28: =BL28*L28 -> 0 | BP28: =BL28*M28 -> 0 | BQ28: =BL28*N28 -> 0 | BU28: =BW28*I28 -> 0 | BW28: 0 | BX28: =BW28*U28 -> 0 | BY28: =BW28*V28 -> 0 | BZ28: =BW28*W28 -> 0 | CA28: =BW28*X28 -> 0 | CB28: =BW28*Y28 -> 0 | CF28: 0 | CH28: 0 | CI28: =CH28*J28 -> 0 | CJ28: =CH28*AG28 -> 0 | CK28: =CH28*AH28 -> 0 | CL28: =CH28*AI28 -> 0 | CM28: =CH28*AJ28 -> 0
A29: Salty snacks | B29: 98.6 | C29: 4.8 | D29: 56.6 (2.2) | E29: 2.9 (0.1) | F29: =B29/I29 -> 17.691901 | G29: =F29*J29 -> 1.5143552 | I29: =0.6*'nutrient content'!B44/100+0.4*'nutrient content'!B275/100 -> 5.5731717 | J29: =0.6*'nutrient content'!C44/100+0.4*'nutrient content'!C275/100 -> 0.08559596 | K29: =0.6*enviro!AD12+0.4*enviro!AD16 -> 0.011328421 | L29: =0.6*enviro!AE12+0.4*enviro!AE16 -> 0.28976432 | M29: =0.6*enviro!AF12+0.4*enviro!AF16 -> 4.1307419 | N29: =0.6*enviro!AG12+0.4*enviro!AG16 -> 0.0018591862 | O29: assumed 0.6 refined grains and 0.4 veg oils | U29: =B29*$U$46 -> 152.2384 | W29: =U29/I29 -> 27.316295 | X29: =W29*J29 -> 2.3381644 | Y29: =$W29*K29 -> 0.30945047 | Z29: =$W29*L29 -> 7.9152874 | AA29: =$W29*M29 -> 112.83656 | AB29: =$W29*N29 -> 0.050786078 | AE29: =U29 -> 152.2384 | AG29: =AE29/I29 -> 27.316295 | AH29: =AG29*J29 -> 2.3381644 | AI29: =$AG29*K29 -> 0.30945047 | AJ29: =$AG29*L29 -> 7.9152874 | AK29: =$AG29*M29 -> 112.83656 | AL29: =$AG29*N29 -> 0.050786078 | AO29: 0 | AQ29: =AO29/I29 -> 0 | AR29: 0 | AS29: =AQ29*K29 -> 0 | AT29: =AQ29*L29 -> 0 | AU29: =AQ29*M29 -> 0 | AV29: =AQ29*N29 -> 0 | AY29: 0 | BA29: =AY29/I29 -> 0 | BB29: 0 | BC29: =BA29*K29 -> 0 | BD29: =BA29*L29 -> 0 | BE29: =BA29*M29 -> 0 | BF29: =BA29*N29 -> 0 | BJ29: 0 | BL29: =BJ29/I29 -> 0 | BM29: =BL29*J29 -> 0 | BN29: =BL29*K29 -> 0 | BO29: =BL29*L29 -> 0 | BP29: =BL29*M29 -> 0 | BQ29: =BL29*N29 -> 0 | BU29: =BW29*I29 -> 0 | BW29: 0 | BX29: =BW29*U29 -> 0 | BY29: =BW29*V29 -> 0 | BZ29: =BW29*W29 -> 0 | CA29: =BW29*X29 -> 0 | CB29: =BW29*Y29 -> 0 | CF29: 0 | CH29: 0 | CI29: =CH29*J29 -> 0 | CJ29: =CH29*AG29 -> 0 | CK29: =CH29*AH29 -> 0 | CL29: =CH29*AI29 -> 0 | CM29: =CH29*AJ29 -> 0
A30: Frozen and shelf-stable plate meals | B30: 58.8 | C30: 2.8 | D30: 58.8 (4.3) | E30: 2.8 (0.2) | F30: =B30/I30 -> 28.150924 | G30: =F30*J30 -> 3.2614339 | I30: =0.7*AVERAGE('nutrient content'!B44,'nutrient content'!L194)/100+0.3*'nutrient content'!B125/100 -> 2.0887414 | J30: =0.7*AVERAGE('nutrient content'!C44,'nutrient content'!M194)/100+0.3*'nutrient content'!C125/100 -> 0.1158553 | K30: =0.7*AVERAGE(enviro!AD12,enviro!AD18,enviro!AD19)+0.3*enviro!AD22 -> 0.084898082 | L30: =0.7*AVERAGE(enviro!AE12,enviro!AE18,enviro!AE19)+0.3*enviro!AE22 -> 0.17832775 | M30: =0.7*AVERAGE(enviro!AF12,enviro!AF18,enviro!AF19)+0.3*enviro!AF22 -> 4.0043839 | N30: =0.7*AVERAGE(enviro!AG12,enviro!AG18,enviro!AG19)+0.3*enviro!AG22 -> 0.0068522876 | O30: assumed 70% average of refined grains, poultry and red and processed meat, and 30% of vegetables | U30: =B30 -> 58.8 | W30: =U30/I30 -> 28.150924 | X30: =W30*J30 -> 3.2614339 | Y30: =$W30*K30 -> 2.3899595 | Z30: =$W30*L30 -> 5.0200911 | AA30: =$W30*M30 -> 112.72711 | AB30: =$W30*N30 -> 0.19289823 | AE30: =U30 -> 58.8 | AG30: =AE30/I30 -> 28.150924 | AH30: =AG30*J30 -> 3.2614339 | AI30: =$AG30*K30 -> 2.3899595 | AJ30: =$AG30*L30 -> 5.0200911 | AK30: =$AG30*M30 -> 112.72711 | AL30: =$AG30*N30 -> 0.19289823 | AO30: 0 | AQ30: =AO30/I30 -> 0 | AR30: 0 | AS30: =AQ30*K30 -> 0 | AT30: =AQ30*L30 -> 0 | AU30: =AQ30*M30 -> 0 | AV30: =AQ30*N30 -> 0 | AY30: 0 | BA30: =AY30/I30 -> 0 | BB30: 0 | BC30: =BA30*K30 -> 0 | BD30: =BA30*L30 -> 0 | BE30: =BA30*M30 -> 0 | BF30: =BA30*N30 -> 0 | BJ30: 0 | BL30: =BJ30/I30 -> 0 | BM30: =BL30*J30 -> 0 | BN30: =BL30*K30 -> 0 | BO30: =BL30*L30 -> 0 | BP30: =BL30*M30 -> 0 | BQ30: =BL30*N30 -> 0 | BU30: 0 | BW30: 0 | BX30: =BW30*U30 -> 0 | BY30: =BW30*V30 -> 0 | BZ30: =BW30*W30 -> 0 | CA30: =BW30*X30 -> 0 | CB30: =BW30*Y30 -> 0 | CF30: 0 | CH30: 0 | CI30: =CH30*AF30 -> 0 | CJ30: =CH30*AG30 -> 0 | CK30: =CH30*AH30 -> 0 | CL30: =CH30*AI30 -> 0 | CM30: =CH30*AJ30 -> 0
A31: Soft drinks, carbonated | B31: 69 | C31: 3.1 | D31: 69.0 (5.0) | E31: 3.1 (0.3) | F31: =B31/I31 -> 176.92308 | G31: =F31*J31 -> 0 | I31: ='nutrient content'!G266/100 -> 0.39 | J31: ='nutrient content'!H266/100 -> 0 | K31: =enviro!AD6 -> 0.00027044745 | L31: =enviro!AE6 -> 0.014529734 | M31: =enviro!AF6 -> 0.030199181 | N31: =enviro!AG6 -> 7.09962e-05 | O31: SSB | U31: =B31*$U$46 -> 106.536 | W31: =U31/I31 -> 273.16923 | X31: =W31*J31 -> 0 | Y31: =$W31*K31 -> 0.073877922 | Z31: =$W31*L31 -> 3.9690762 | AA31: =$W31*M31 -> 8.249487 | AB31: =$W31*N31 -> 0.019393977 | AE31: =U31 -> 106.536 | AG31: =AE31/I31 -> 273.16923 | AH31: =AG31*J31 -> 0 | AI31: =$AG31*K31 -> 0.073877922 | AJ31: =$AG31*L31 -> 3.9690762 | AK31: =$AG31*M31 -> 8.249487 | AL31: =$AG31*N31 -> 0.019393977 | AO31: 0 | AQ31: =AO31/I31 -> 0 | AR31: 0 | AS31: =AQ31*K31 -> 0 | AT31: =AQ31*L31 -> 0 | AU31: =AQ31*M31 -> 0 | AV31: =AQ31*N31 -> 0 | AY31: 0 | BA31: =AY31/I31 -> 0 | BB31: 0 | BC31: =BA31*K31 -> 0 | BD31: =BA31*L31 -> 0 | BE31: =BA31*M31 -> 0 | BF31: =BA31*N31 -> 0 | BJ31: 0 | BL31: =BJ31/I31 -> 0 | BM31: =BL31*J31 -> 0 | BN31: =BL31*K31 -> 0 | BO31: =BL31*L31 -> 0 | BP31: =BL31*M31 -> 0 | BQ31: =BL31*N31 -> 0 | BU31: 0 | BW31: 0 | BX31: =BW31*U31 -> 0 | BY31: =BW31*V31 -> 0 | BZ31: =BW31*W31 -> 0 | CA31: =BW31*X31 -> 0 | CB31: =BW31*Y31 -> 0 | CF31: 0 | CH31: 0 | CI31: =CH31*AF31 -> 0 | CJ31: =CH31*AG31 -> 0 | CK31: =CH31*AH31 -> 0 | CL31: =CH31*AI31 -> 0 | CM31: =CH31*AJ31 -> 0
A32: Pizza (ready-to-eat/heat) | B32: 74.9 | C32: 3.4 | D32: 74.9 (2.8) | E32: 3.4 (0.2) | F32: =B32/I32 -> 25.217794 | G32: =F32*J32 -> 3.0671142 | I32: =0.4*'nutrient content'!B5/100+0.35*'nutrient content'!L211/100+0.15*'nutrient content'!G85/100+0.1*'nutrient content'!B255/100 -> 2.970125 | J32: =0.4*'nutrient content'!C5/100+0.35*'nutrient content'!M211/100+0.15*'nutrient content'!H85/100+0.1*'nutrient content'!C255/100 -> 0.121625 | K32: =0.4*enviro!R128+0.35*enviro!R55+0.15*enviro!R282+0.1*enviro!R178 -> 0.017941114 | L32: =0.4*enviro!S128+0.35*enviro!S55+0.15*enviro!S282+0.1*enviro!S178 -> 0.079244372 | M32: =0.4*enviro!T128+0.35*enviro!T55+0.15*enviro!T282+0.1*enviro!T178 -> 11.726841 | N32: =0.4*enviro!U128+0.35*enviro!U55+0.15*enviro!U282+0.1*enviro!U178 -> 0.0030149259 | O32: assumed 40% flour 35% cheese, veg 15% (tomato) and then 10% veg oils | U32: =B32*$U$46 -> 115.6456 | W32: =U32/I32 -> 38.936274 | X32: =W32*J32 -> 4.7356243 | Y32: =$W32*K32 -> 0.69856012 | Z32: =$W32*L32 -> 3.0854806 | AA32: =$W32*M32 -> 456.59948 | AB32: =$W32*N32 -> 0.11738998 | AE32: =U32 -> 115.6456 | AG32: =AE32/I32 -> 38.936274 | AH32: =AG32*J32 -> 4.7356243 | AI32: =$AG32*K32 -> 0.69856012 | AJ32: =$AG32*L32 -> 3.0854806 | AK32: =$AG32*M32 -> 456.59948 | AL32: =$AG32*N32 -> 0.11738998 | AO32: 0 | AQ32: =AO32/I32 -> 0 | AR32: 0 | AS32: =AQ32*K32 -> 0 | AT32: =AQ32*L32 -> 0 | AU32: =AQ32*M32 -> 0 | AV32: =AQ32*N32 -> 0 | AY32: 0 | BA32: =AY32/I32 -> 0 | BB32: 0 | BC32: =BA32*K32 -> 0 | BD32: =BA32*L32 -> 0 | BE32: =BA32*M32 -> 0 | BF32: =BA32*N32 -> 0 | BJ32: 0 | BL32: =BJ32/I32 -> 0 | BM32: =BL32*J32 -> 0 | BN32: =BL32*K32 -> 0 | BO32: =BL32*L32 -> 0 | BP32: =BL32*M32 -> 0 | BQ32: =BL32*N32 -> 0 | BU32: 0 | BW32: 0 | BX32: =BW32*U32 -> 0 | BY32: =BW32*V32 -> 0 | BZ32: =BW32*W32 -> 0 | CA32: =BW32*X32 -> 0 | CB32: =BW32*Y32 -> 0 | CF32: 0 | CH32: 0 | CI32: =CH32*AF32 -> 0 | CJ32: =CH32*AG32 -> 0 | CK32: =CH32*AH32 -> 0 | CL32: =CH32*AI32 -> 0 | CM32: =CH32*AJ32 -> 0
A33: Fruit drinks | B33: 58.3 | C33: 2.9 | D33: 58.3 (3.3) | E33: 2.9 (0.2) | F33: =B33/I33 -> 95.289747 | G33: =F33*J33 -> 0.58040119 | I33: =AVERAGE('nutrient content'!G96,'nutrient content'!G98,'nutrient content'!G107,'nutrient content'!G120,'nutrient content'!G125,'nutrient content'!G130,'nutrient content'!G138,'nutrient content'!B130,'nutrient content'!B133,'nutrient content'!B138,'nutrient content'!B141)/100 -> 0.61181818 | J33: =AVERAGE('nutrient content'!H96,'nutrient content'!H98,'nutrient content'!H107,'nutrient content'!H120,'nutrient content'!H125,'nutrient content'!H130,'nutrient content'!H138,'nutrient content'!C130,'nutrient content'!C133,'nutrient content'!C138,'nutrient content'!C141)/100 -> 0.0060909091 | K33: =enviro!AD11 -> 0.0023035092 | L33: =enviro!AE11 -> 0.026136647 | M33: =enviro!AF11 -> 2.6729545 | N33: =enviro!AG11 -> 0.0006384849 | O33: assumed fruits - caloric difference between fruits nd fruits juice is negligable | U33: =B33*$U$46 -> 90.0152 | W33: =U33/I33 -> 147.12737 | X33: =W33*J33 -> 0.89613944 | Y33: =$W33*K33 -> 0.33890925 | Z33: =$W33*L33 -> 3.8454162 | AA33: =$W33*M33 -> 393.26477 | AB33: =$W33*N33 -> 0.093938604 | AE33: =U33 -> 90.0152 | AG33: =AE33/I33 -> 147.12737 | AH33: =AG33*J33 -> 0.89613944 | AI33: =$AG33*K33 -> 0.33890925 | AJ33: =$AG33*L33 -> 3.8454162 | AK33: =$AG33*M33 -> 393.26477 | AL33: =$AG33*N33 -> 0.093938604 | AO33: 0 | AQ33: =AO33/I33 -> 0 | AR33: 0 | AS33: =AQ33*K33 -> 0 | AT33: =AQ33*L33 -> 0 | AU33: =AQ33*M33 -> 0 | AV33: =AQ33*N33 -> 0 | AY33: 0 | BA33: =AY33/I33 -> 0 | BB33: 0 | BC33: =BA33*K33 -> 0 | BD33: =BA33*L33 -> 0 | BE33: =BA33*M33 -> 0 | BF33: =BA33*N33 -> 0 | BJ33: 0 | BL33: =BJ33/I33 -> 0 | BM33: =BL33*J33 -> 0 | BN33: =BL33*K33 -> 0 | BO33: =BL33*L33 -> 0 | BP33: =BL33*M33 -> 0 | BQ33: =BL33*N33 -> 0 | BU33: 0 | BW33: 0 | BX33: =BW33*U33 -> 0 | BY33: =BW33*V33 -> 0 | BZ33: =BW33*W33 -> 0 | CA33: =BW33*X33 -> 0 | CB33: =BW33*Y33 -> 0 | CF33: 0 | CH33: 0 | CI33: =CH33*AF33 -> 0 | CJ33: =CH33*AG33 -> 0 | CK33: =CH33*AH33 -> 0 | CL33: =CH33*AI33 -> 0 | CM33: =CH33*AJ33 -> 0
A34: Breakfast cereals | B34: 42.8 | C34: 2.2 | D34: 37.4 (1.3) | E34: 1.9 (0.1) | F34: =B34/I34 -> 12.995752 | G34: =F34*J34 -> 0.93661304 | I34: =AVERAGE('nutrient content'!B44,'nutrient content'!B60)/100 -> 3.2933838 | J34: =AVERAGE('nutrient content'!C44,'nutrient content'!C60)/100 -> 0.072070707 | K34: =AVERAGE(enviro!AD20,enviro!AD12) -> 0.018451704 | L34: =AVERAGE(enviro!AE20,enviro!AE12) -> 0.11522772 | M34: =AVERAGE(enviro!AF20,enviro!AF12) -> 3.9250933 | N34: =AVERAGE(enviro!AG20,enviro!AG12) -> 0.001437584 | O34: assumed average of refined grains and sweets | U34: =B34*$U$46 -> 66.0832 | W34: =U34/I34 -> 20.065441 | X34: =W34*J34 -> 1.4461305 | Y34: =$W34*K34 -> 0.37024158 | Z34: =$W34*L34 -> 2.3120951 | AA34: =$W34*M34 -> 78.758729 | AB34: =$W34*N34 -> 0.028845757 | AE34: =U34 -> 66.0832 | AG34: =AE34/I34 -> 20.065441 | AH34: =AG34*J34 -> 1.4461305 | AI34: =$AG34*K34 -> 0.37024158 | AJ34: =$AG34*L34 -> 2.3120951 | AK34: =$AG34*M34 -> 78.758729 | AL34: =$AG34*N34 -> 0.028845757 | AO34: 0 | AQ34: =AO34/I34 -> 0 | AR34: 0 | AS34: =AQ34*K34 -> 0 | AT34: =AQ34*L34 -> 0 | AU34: =AQ34*M34 -> 0 | AV34: =AQ34*N34 -> 0 | AY34: 0 | BA34: =AY34/I34 -> 0 | BB34: 0 | BC34: =BA34*K34 -> 0 | BD34: =BA34*L34 -> 0 | BE34: =BA34*M34 -> 0 | BF34: =BA34*N34 -> 0 | BJ34: 0 | BL34: =BJ34/I34 -> 0 | BM34: =BL34*J34 -> 0 | BN34: =BL34*K34 -> 0 | BO34: =BL34*L34 -> 0 | BP34: =BL34*M34 -> 0 | BQ34: =BL34*N34 -> 0 | BU34: 0 | BW34: 0 | BX34: =BW34*U34 -> 0 | BY34: =BW34*V34 -> 0 | BZ34: =BW34*W34 -> 0 | CA34: =BW34*X34 -> 0 | CB34: =BW34*Y34 -> 0 | CF34: 0 | CH34: 0 | CI34: =CH34*AF34 -> 0 | CJ34: =CH34*AG34 -> 0 | CK34: =CH34*AH34 -> 0 | CL34: =CH34*AI34 -> 0 | CM34: =CH34*AJ34 -> 0
A35: Sauces, dressings, and gravies | B35: 67.8 | C35: 3.2 | D35: 67.8 (2.8) | E35: 3.2 (0.1) | F35: =B35/I35 -> 8.883883 | G35: =F35*J35 -> 0.25610709 | I35: ='nutrient content'!B44*0.2/100+0.8*'nutrient content'!B275/100 -> 7.631798 | J35: ='nutrient content'!C44*0.2/100+0.8*'nutrient content'!C275/100 -> 0.028828283 | K35: =0.1*enviro!AD12+0.1*enviro!AD13+0.8*enviro!AD16 -> 0.014609151 | L35: =0.1*enviro!AE12+0.1*enviro!AE13+0.8*enviro!AE16 -> 0.43290178 | M35: =0.1*enviro!AF12+0.1*enviro!AF13+0.8*enviro!AF16 -> 6.5255908 | N35: =0.1*enviro!AG12+0.1*enviro!AG13+0.8*enviro!AG16 -> 0.0025373337 | O35: assumed 80% average fats, 10% grains, 10% refined grains | U35: =B35*$U$46 -> 104.6832 | W35: =U35/I35 -> 13.716715 | X35: =W35*J35 -> 0.39542935 | Y35: =$W35*K35 -> 0.20038957 | Z35: =$W35*L35 -> 5.9379904 | AA35: =$W35*M35 -> 89.509672 | AB35: =$W35*N35 -> 0.034803883 | AE35: =U35 -> 104.6832 | AG35: =AE35/I35 -> 13.716715 | AH35: =AG35*J35 -> 0.39542935 | AI35: =$AG35*K35 -> 0.20038957 | AJ35: =$AG35*L35 -> 5.9379904 | AK35: =$AG35*M35 -> 89.509672 | AL35: =$AG35*N35 -> 0.034803883 | AO35: 0 | AQ35: =AO35/I35 -> 0 | AR35: 0 | AS35: =AQ35*K35 -> 0 | AT35: =AQ35*L35 -> 0 | AU35: =AQ35*M35 -> 0 | AV35: =AQ35*N35 -> 0 | AY35: 0 | BA35: =AY35/I35 -> 0 | BB35: 0 | BC35: =BA35*K35 -> 0 | BD35: =BA35*L35 -> 0 | BE35: =BA35*M35 -> 0 | BF35: =BA35*N35 -> 0 | BJ35: 0 | BL35: =BJ35/I35 -> 0 | BM35: =BL35*J35 -> 0 | BN35: =BL35*K35 -> 0 | BO35: =BL35*L35 -> 0 | BP35: =BL35*M35 -> 0 | BQ35: =BL35*N35 -> 0 | BU35: 0 | BW35: 0 | BX35: =BW35*U35 -> 0 | BY35: =BW35*V35 -> 0 | BZ35: =BW35*W35 -> 0 | CA35: =BW35*X35 -> 0 | CB35: =BW35*Y35 -> 0 | CF35: 0 | CH35: 0 | CI35: =CH35*AF35 -> 0 | CJ35: =CH35*AG35 -> 0 | CK35: =CH35*AH35 -> 0 | CL35: =CH35*AI35 -> 0 | CM35: =CH35*AJ35 -> 0
A36: Ice cream and ice pops | B36: 40.3 | C36: 1.9 | D36: 40.3 (2.6) | E36: 1.9 (0.1) | F36: =B36/I36 -> 10.596092 | G36: =F36*J36 -> 0.18745665 | I36: =0.67*'nutrient content'!B60/100+0.17*'nutrient content'!L210/100+0.17*'nutrient content'!B280/100 -> 3.8032889 | J36: =0.67*'nutrient content'!C60/100+0.17*'nutrient content'!M210/100+0.17*'nutrient content'!C280/100 -> 0.017691111 | K36: =0.67*enviro!R248+0.165*enviro!R33+0.165*enviro!R44 -> 0.0019797908 | L36: =0.67*enviro!S248+0.165*enviro!S33+0.165*enviro!S44 -> 0.013602906 | M36: =0.67*enviro!T248+0.165*enviro!T33+0.165*enviro!T44 -> 1.59687 | N36: =0.67*enviro!U248+0.165*enviro!U33+0.165*enviro!U44 -> 0.00059652625 | O36: assumed 50% ice pop+50% ice cream--> 50% sugar +17% sugar 17% milk fat and 17% milk | U36: =B36*$U$46 -> 62.2232 | W36: =U36/I36 -> 16.360366 | X36: =W36*J36 -> 0.28943306 | Y36: =$W36*K36 -> 0.032390102 | Z36: =$W36*L36 -> 0.22254853 | AA36: =$W36*M36 -> 26.125378 | AB36: =$W36*N36 -> 0.0097593881 | AE36: =U36 -> 62.2232 | AG36: =AE36/I36 -> 16.360366 | AH36: =AG36*J36 -> 0.28943306 | AI36: =$AG36*K36 -> 0.032390102 | AJ36: =$AG36*L36 -> 0.22254853 | AK36: =$AG36*M36 -> 26.125378 | AL36: =$AG36*N36 -> 0.0097593881 | AO36: 0 | AQ36: =AO36/I36 -> 0 | AR36: 0 | AS36: =AQ36*K36 -> 0 | AT36: =AQ36*L36 -> 0 | AU36: =AQ36*M36 -> 0 | AV36: =AQ36*N36 -> 0 | AY36: 0 | BA36: =AY36/I36 -> 0 | BB36: 0 | BC36: =BA36*K36 -> 0 | BD36: =BA36*L36 -> 0 | BE36: =BA36*M36 -> 0 | BF36: =BA36*N36 -> 0 | BJ36: 0 | BL36: =BJ36/I36 -> 0 | BM36: =BL36*J36 -> 0 | BN36: =BL36*K36 -> 0 | BO36: =BL36*L36 -> 0 | BP36: =BL36*M36 -> 0 | BQ36: =BL36*N36 -> 0 | BU36: 0 | BW36: 0 | BX36: =BW36*U36 -> 0 | BY36: =BW36*V36 -> 0 | BZ36: =BW36*W36 -> 0 | CA36: =BW36*X36 -> 0 | CB36: =BW36*Y36 -> 0 | CF36: 0 | CH36: 0 | CI36: =CH36*AF36 -> 0 | CJ36: =CH36*AG36 -> 0 | CK36: =CH36*AH36 -> 0 | CL36: =CH36*AI36 -> 0 | CM36: =CH36*AJ36 -> 0
A37: Sweet snacks | B37: 57.4 | C37: 2.8 | D37: 57.4 (3.0) | E37: 2.8 (0.1) | F37: =B37/I37 -> 16.753837 | G37: =F37*J37 -> 1.9140667 | I37: =0.2*'nutrient content'!B60/100+0.8*'nutrient content'!B44/100 -> 3.4260808 | J37: =0.2*'nutrient content'!C60/100+0.8*'nutrient content'!C44/100 -> 0.11424646 | K37: =0.8*enviro!AD13+0.2*enviro!R248 -> 0.0047069498 | L37: =0.8*enviro!AE13+0.2*enviro!S248 -> 0.079023291 | M37: =0.8*enviro!AF13+0.2*enviro!T248 -> 0.94560202 | N37: =0.8*enviro!AG13+0.2*enviro!U248 -> 0.00043261901 | O37: assumed 80% grains+20% sugar | U37: =B37*$U$46 -> 88.6256 | W37: =U37/I37 -> 25.867925 | X37: =W37*J37 -> 2.9553189 | Y37: =$W37*K37 -> 0.12175902 | Z37: =$W37*L37 -> 2.0441685 | AA37: =$W37*M37 -> 24.460762 | AB37: =$W37*N37 -> 0.011190956 | AE37: =U37 -> 88.6256 | AG37: =AE37/I37 -> 25.867925 | AH37: =AG37*J37 -> 2.9553189 | AI37: =$AG37*K37 -> 0.12175902 | AJ37: =$AG37*L37 -> 2.0441685 | AK37: =$AG37*M37 -> 24.460762 | AL37: =$AG37*N37 -> 0.011190956 | AO37: 0 | AQ37: =AO37/I37 -> 0 | AR37: 0 | AS37: =AQ37*K37 -> 0 | AT37: =AQ37*L37 -> 0 | AU37: =AQ37*M37 -> 0 | AV37: =AQ37*N37 -> 0 | AY37: 0 | BA37: =AY37/I37 -> 0 | BB37: 0 | BC37: =BA37*K37 -> 0 | BD37: =BA37*L37 -> 0 | BE37: =BA37*M37 -> 0 | BF37: =BA37*N37 -> 0 | BJ37: 0 | BL37: =BJ37/I37 -> 0 | BM37: =BL37*J37 -> 0 | BN37: =BL37*K37 -> 0 | BO37: =BL37*L37 -> 0 | BP37: =BL37*M37 -> 0 | BQ37: =BL37*N37 -> 0 | BU37: 0 | BW37: 0 | BX37: =BW37*U37 -> 0 | BY37: =BW37*V37 -> 0 | BZ37: =BW37*W37 -> 0 | CA37: =BW37*X37 -> 0 | CB37: =BW37*Y37 -> 0 | CF37: 0 | CH37: 0 | CI37: =CH37*AF37 -> 0 | CJ37: =CH37*AG37 -> 0 | CK37: =CH37*AH37 -> 0 | CL37: =CH37*AI37 -> 0 | CM37: =CH37*AJ37 -> 0
